 * Running on http://0.0.0.0:5000/ (Press CTRL+C to quit)
 * Restarting with stat
 * Debugger is active!
 * Debugger pin code: 784-244-215
 * Detected change in '/sites/nii-challenge/app/headers/views.py', reloading
 * Restarting with stat
 * Debugger is active!
 * Debugger pin code: 318-755-867
Traceback (most recent call last):
  File "run.py", line 9, in <module>
    debug=app.config['DEBUG'])
  File "/sites/nii-challenge/venv-3.4/lib/python3.4/site-packages/flask/app.py", line 772, in run
    run_simple(host, port, self, **options)
  File "/sites/nii-challenge/venv-3.4/lib/python3.4/site-packages/werkzeug/serving.py", line 677, in run_simple
    s.bind((hostname, port))
OSError: [Errno 98] Address already in use
115.110.127.198 - - [04/Jul/2016 12:53:47] "GET / HTTP/1.1" 200 -
115.110.127.198 - - [04/Jul/2016 12:54:03] "POST /api/v1/headers/user.json HTTP/1.1" 201 -
115.110.127.198 - - [04/Jul/2016 12:54:04] "GET / HTTP/1.1" 200 -
 * Detected change in '/sites/nii-challenge/app/headers/views.py', reloading
Exception ignored in: <module 'threading' from '/usr/lib/python3.4/threading.py'>
Traceback (most recent call last):
  File "/usr/lib/python3.4/threading.py", line 1296, in _shutdown
    _main_thread._delete()
  File "/usr/lib/python3.4/threading.py", line 1019, in _delete
    del _active[get_ident()]
  File "/sites/nii-challenge/venv-3.4/lib/python3.4/site-packages/gevent/threading.py", line 110, in __delitem__
    dict.__delitem__(self, k)
KeyError: 139894189590984
 * Restarting with stat
Traceback (most recent call last):
  File "run.py", line 4, in <module>
    app = create_app('config')
  File "/sites/nii-challenge/app/__init__.py", line 11, in create_app
    from app.basemodels import db
ImportError: No module named 'app.basemodels'
